# 对异常进行捕获与抛出

## 捕获异常
在Java中，凡是可能抛出异常的语句，都可以用try ... catch捕获。把可能发生异常的语句放在try { ... }中，然后使用catch捕获对应的Exception及其子类    

### 多catch语句 
我们可以使用一个try以及多个catch来捕获对应的Exception及其子类   
JVM在捕获到异常后，会从上到下匹配catch语句，匹配到某个catch后，执行catch代码块，然后不再继续匹配    
> 简单来说就是从上到下找解决方案，找到了就不去找其他的方案了    
> 多个catch只能有一个能被执行

```Java
public static void main(String[] args) {
    try {
        process1();
        process2();
        process3();
    } catch (IOException e) {
        System.out.println(e);
    } catch (NumberFormatException e) {
        System.out.println(e);
    }
}
```

因为**从上到下查找**的机制，所以我们安排```catch```的顺序是十分重要的，特别是**必须把子类写在前面** 
如果我们不这么做，子类的异常是永远不会捕获到的：因为它的父类(比如IOException)总是有比它更大的范围，如果父类在前，肯定就直接使用父类catch的方案了    

所以，上面的代码的更正确的写法应该是：
```Java
public static void main(String[] args) {
    try {
        process1();
        process2();
        process3();
    } catch (UnsupportedEncodingException e) {
        System.out.println("Bad encoding");
    } catch (IOException e) {
        System.out.println("IO error");
    }
}
```

### Finally语句
> 论是否有异常发生，我们都希望执行的一些语句       

```finally```语句块保证有无错误都会执行    

```Java
public static void main(String[] args) {
    try {
        process1();
        process2();
        process3();
    } catch (UnsupportedEncodingException e) {
        System.out.println("Bad encoding");
    } catch (IOException e) {
        System.out.println("IO error");
    } finally {
        System.out.println("END");
    }
```

Finally具有以下几个特点:
1.finally语句不是必须的，可写可不写；
2.finally**总是最后执行**   

> 某些情况下，可以没有catch，只使用try ... finally结构。这种事情一般发生在方法声明了可抛出异常的时候————此时我们只需要做好try和finally即可  

### 捕获多种异常
如果某些异常的处理逻辑相同，但是异常本身不存在继承关系，那么就得编写多条catch子句   
不过此时如果发现某些子句具有相同的执行逻辑，那么就可以利用```|```将它们合二为一 

```Java
public static void main(String[] args) {
    try {
        process1();
        process2();
        process3();
    } catch (IOException e) {
        System.out.println("Bad input");
    } catch (NumberFormatException e) {
        System.out.println("Bad input");
    } catch (Exception e) {
        System.out.println("Unknown error");
    }
}
```

这时候发现```IOException```与```NumberFormatException```的处理代码是相同的，那么我们就可以把它们合在一起。于是代码可以修改为:
```Java
public static void main(String[] args) {
    try {
        process1();
        process2();
        process3();
    } catch (IOException | NumberFormatException e) { 
        // IOException或NumberFormatException
        System.out.println("Bad input");
    } catch (Exception e) {
        System.out.println("Unknown error");
    }
}
```

## 抛出异常

### 异常的传播
和抛出的传播“相反”，当某个方法抛出了异常时，如果当前方法没有捕获异常，异常就会被抛到上层调用方法，直到遇到某个```try ... catch```被捕获为止 

比如说对于:
```Java
public class Main {
    public static void main(String[] args) {
        try {
            process1();
        } catch (Exception e) {
            e.printStackTrace();
        }
    }

    static void process1() {
        process2();
    }

    static void process2() {
        Integer.parseInt(null); // 会抛出NumberFormatException
    }
}
```

我们利用```printStackTrace()```来打印出方法的调用栈 
于是可以发现：
```
1.main()调用process1()；
2.process1()调用process2()；
3.process2()调用Integer.parseInt(String)；
4.Integer.parseInt(String)调用Integer.parseInt(String, int)
```

### 抛出异常
当发生错误时，例如，用户输入了非法的字符，我们就可以抛出异常，抛出异常分为两步：    
1.创建某个Exception的实例   
2.用throw语句抛出   

比如我们的方法需要一个字符串，然而却被传入了一个null，那么我们就可以来抛出它：
```Java
void process2(String s ){
    if(s==null){
        NullPointerException e = new NullPointerException();
        throw e;
    }
}

//实际上，大部分的抛出异常会被写作一行

void process2(String s){
    if(s==null){
        throw new NullPointerException();
    }
}
``` 

#### "异常类型转换"
> 如果一个方法捕获了某个异常后，又在catch子句中抛出新的异常，就相当于把抛出的异常类型“转换”了   

```Java
void process1(String s) {
    try {
        process2();
    } catch (NullPointerException e) {
        throw new IllegalArgumentException();
    }
}

void process2(String s) {
    if (s==null) {
        throw new NullPointerException();
    }
}
```

当process2()抛出NullPointerException后，被process1()捕获，然后抛出IllegalArgumentException()    

```Java
public class Main {
    public static void main(String[] args) {
        try {
            process1();
        } catch (Exception e) {
            e.printStackTrace();
        }
    }

    static void process1() {
        try {
            process2();
        } catch (NullPointerException e) {
            throw new IllegalArgumentException();
        }
    }

    static void process2() {
        throw new NullPointerException();
    }
}

```

> 注意：新的异常会丢失原始异常信息
为了能追踪到完整的异常栈，在构造异常的时候，把原始的Exception实例传进去，新的Exception就可以持有原始Exception信息   

> 在代码中获取原始异常可以使用Throwable.getCause()方法。如果返回null，说明已经是“根异常”了。

有了完整的异常栈的信息，我们才能快速定位并修复代码的问题

另外，在catch中抛出异常，不会影响finally的执行。JVM会先执行finally，然后抛出异常    

### 异常屏蔽
如果我们突发奇想，在finally中抛出异常，我们就会发现：
finally抛出异常后，原来在catch中准备抛出的异常就“消失”了，因为只能抛出一个异常。没有被抛出的异常称为“被屏蔽”的异常（Suppressed Exception）

> 在极少数的情况下，我们需要获知所有的异常。如何保存所有的异常信息？方法是先用origin变量保存原始异常，然后调用Throwable.addSuppressed()，把原始异常添加进来，最后在finally抛出  

> 当catch和finally都抛出了异常时，虽然catch的异常被屏蔽了，但是，finally抛出的异常仍然包含了它  

绝大多数情况下，在finally中不要抛出异常 